python3: can't open file '/home/ubuntu/LawGPT_api/uvicorn': [Errno 2] No such file or directory
INFO:     Started server process [60680]
INFO:     Waiting for application startup.
INFO:     Application startup complete.
INFO:     Uvicorn running on http://127.0.0.1:8000 (Press CTRL+C to quit)
INFO:     127.0.0.1:34946 - "GET /docs HTTP/1.0" 200 OK
INFO:     127.0.0.1:34950 - "GET /openapi.json HTTP/1.0" 200 OK
{'_id': ObjectId('6555e651ba939ed5811894de'), 'name': 'string', 'email': 'user2@example.com', 'password': 'string2'}
INFO:     127.0.0.1:35792 - "POST /signin HTTP/1.0" 200 OK
INFO:     127.0.0.1:56326 - "GET /userid HTTP/1.0" 500 Internal Server Error
ERROR:    Exception in ASGI application
Traceback (most recent call last):
  File "/home/ubuntu/.local/lib/python3.10/site-packages/uvicorn/protocols/http/httptools_impl.py", line 426, in run_asgi
    result = await app(  # type: ignore[func-returns-value]
  File "/home/ubuntu/.local/lib/python3.10/site-packages/uvicorn/middleware/proxy_headers.py", line 84, in __call__
    return await self.app(scope, receive, send)
  File "/home/ubuntu/.local/lib/python3.10/site-packages/fastapi/applications.py", line 292, in __call__
    await super().__call__(scope, receive, send)
  File "/home/ubuntu/.local/lib/python3.10/site-packages/starlette/applications.py", line 122, in __call__
    await self.middleware_stack(scope, receive, send)
  File "/home/ubuntu/.local/lib/python3.10/site-packages/starlette/middleware/errors.py", line 184, in __call__
    raise exc
  File "/home/ubuntu/.local/lib/python3.10/site-packages/starlette/middleware/errors.py", line 162, in __call__
    await self.app(scope, receive, _send)
  File "/home/ubuntu/.local/lib/python3.10/site-packages/starlette/middleware/base.py", line 108, in __call__
    response = await self.dispatch_func(request, call_next)
  File "/home/ubuntu/LawGPT_api/main.py", line 123, in auth_middleware
    raise HTTPException(status_code=401, detail="Not authenticated")
fastapi.exceptions.HTTPException
{'_id': ObjectId('6555e651ba939ed5811894de'), 'name': 'string', 'email': 'user2@example.com', 'password': 'string2'}
INFO:     127.0.0.1:52662 - "POST /signin HTTP/1.0" 200 OK
INFO:     127.0.0.1:49756 - "GET /userid HTTP/1.0" 200 OK
INFO:     127.0.0.1:44400 - "GET /SessionId HTTP/1.0" 200 OK
INFO:     127.0.0.1:57576 - "GET /history HTTP/1.0" 200 OK
INFO:     127.0.0.1:60818 - "GET /docs HTTP/1.0" 200 OK
INFO:     127.0.0.1:60830 - "GET /openapi.json HTTP/1.0" 200 OK
INFO:     127.0.0.1:40894 - "GET / HTTP/1.0" 500 Internal Server Error
ERROR:    Exception in ASGI application
Traceback (most recent call last):
  File "/home/ubuntu/.local/lib/python3.10/site-packages/uvicorn/protocols/http/httptools_impl.py", line 426, in run_asgi
    result = await app(  # type: ignore[func-returns-value]
  File "/home/ubuntu/.local/lib/python3.10/site-packages/uvicorn/middleware/proxy_headers.py", line 84, in __call__
    return await self.app(scope, receive, send)
  File "/home/ubuntu/.local/lib/python3.10/site-packages/fastapi/applications.py", line 292, in __call__
    await super().__call__(scope, receive, send)
  File "/home/ubuntu/.local/lib/python3.10/site-packages/starlette/applications.py", line 122, in __call__
    await self.middleware_stack(scope, receive, send)
  File "/home/ubuntu/.local/lib/python3.10/site-packages/starlette/middleware/errors.py", line 184, in __call__
    raise exc
  File "/home/ubuntu/.local/lib/python3.10/site-packages/starlette/middleware/errors.py", line 162, in __call__
    await self.app(scope, receive, _send)
  File "/home/ubuntu/.local/lib/python3.10/site-packages/starlette/middleware/base.py", line 108, in __call__
    response = await self.dispatch_func(request, call_next)
  File "/home/ubuntu/LawGPT_api/main.py", line 123, in auth_middleware
    raise HTTPException(status_code=401, detail="Not authenticated")
fastapi.exceptions.HTTPException
INFO:     127.0.0.1:49464 - "GET /.env HTTP/1.0" 500 Internal Server Error
ERROR:    Exception in ASGI application
Traceback (most recent call last):
  File "/home/ubuntu/.local/lib/python3.10/site-packages/uvicorn/protocols/http/httptools_impl.py", line 426, in run_asgi
    result = await app(  # type: ignore[func-returns-value]
  File "/home/ubuntu/.local/lib/python3.10/site-packages/uvicorn/middleware/proxy_headers.py", line 84, in __call__
    return await self.app(scope, receive, send)
  File "/home/ubuntu/.local/lib/python3.10/site-packages/fastapi/applications.py", line 292, in __call__
    await super().__call__(scope, receive, send)
  File "/home/ubuntu/.local/lib/python3.10/site-packages/starlette/applications.py", line 122, in __call__
    await self.middleware_stack(scope, receive, send)
  File "/home/ubuntu/.local/lib/python3.10/site-packages/starlette/middleware/errors.py", line 184, in __call__
    raise exc
  File "/home/ubuntu/.local/lib/python3.10/site-packages/starlette/middleware/errors.py", line 162, in __call__
    await self.app(scope, receive, _send)
  File "/home/ubuntu/.local/lib/python3.10/site-packages/starlette/middleware/base.py", line 108, in __call__
    response = await self.dispatch_func(request, call_next)
  File "/home/ubuntu/LawGPT_api/main.py", line 123, in auth_middleware
    raise HTTPException(status_code=401, detail="Not authenticated")
fastapi.exceptions.HTTPException
INFO:     127.0.0.1:49466 - "POST / HTTP/1.0" 500 Internal Server Error
ERROR:    Exception in ASGI application
Traceback (most recent call last):
  File "/home/ubuntu/.local/lib/python3.10/site-packages/uvicorn/protocols/http/httptools_impl.py", line 426, in run_asgi
    result = await app(  # type: ignore[func-returns-value]
  File "/home/ubuntu/.local/lib/python3.10/site-packages/uvicorn/middleware/proxy_headers.py", line 84, in __call__
    return await self.app(scope, receive, send)
  File "/home/ubuntu/.local/lib/python3.10/site-packages/fastapi/applications.py", line 292, in __call__
    await super().__call__(scope, receive, send)
  File "/home/ubuntu/.local/lib/python3.10/site-packages/starlette/applications.py", line 122, in __call__
    await self.middleware_stack(scope, receive, send)
  File "/home/ubuntu/.local/lib/python3.10/site-packages/starlette/middleware/errors.py", line 184, in __call__
    raise exc
  File "/home/ubuntu/.local/lib/python3.10/site-packages/starlette/middleware/errors.py", line 162, in __call__
    await self.app(scope, receive, _send)
  File "/home/ubuntu/.local/lib/python3.10/site-packages/starlette/middleware/base.py", line 108, in __call__
    response = await self.dispatch_func(request, call_next)
  File "/home/ubuntu/LawGPT_api/main.py", line 123, in auth_middleware
    raise HTTPException(status_code=401, detail="Not authenticated")
fastapi.exceptions.HTTPException
INFO:     127.0.0.1:56962 - "HEAD /Core/Skin/Login.aspx HTTP/1.0" 500 Internal Server Error
ERROR:    Exception in ASGI application
Traceback (most recent call last):
  File "/home/ubuntu/.local/lib/python3.10/site-packages/uvicorn/protocols/http/httptools_impl.py", line 426, in run_asgi
    result = await app(  # type: ignore[func-returns-value]
  File "/home/ubuntu/.local/lib/python3.10/site-packages/uvicorn/middleware/proxy_headers.py", line 84, in __call__
    return await self.app(scope, receive, send)
  File "/home/ubuntu/.local/lib/python3.10/site-packages/fastapi/applications.py", line 292, in __call__
    await super().__call__(scope, receive, send)
  File "/home/ubuntu/.local/lib/python3.10/site-packages/starlette/applications.py", line 122, in __call__
    await self.middleware_stack(scope, receive, send)
  File "/home/ubuntu/.local/lib/python3.10/site-packages/starlette/middleware/errors.py", line 184, in __call__
    raise exc
  File "/home/ubuntu/.local/lib/python3.10/site-packages/starlette/middleware/errors.py", line 162, in __call__
    await self.app(scope, receive, _send)
  File "/home/ubuntu/.local/lib/python3.10/site-packages/starlette/middleware/base.py", line 108, in __call__
    response = await self.dispatch_func(request, call_next)
  File "/home/ubuntu/LawGPT_api/main.py", line 123, in auth_middleware
    raise HTTPException(status_code=401, detail="Not authenticated")
fastapi.exceptions.HTTPException
INFO:     127.0.0.1:51744 - "GET / HTTP/1.0" 500 Internal Server Error
ERROR:    Exception in ASGI application
Traceback (most recent call last):
  File "/home/ubuntu/.local/lib/python3.10/site-packages/uvicorn/protocols/http/httptools_impl.py", line 426, in run_asgi
    result = await app(  # type: ignore[func-returns-value]
  File "/home/ubuntu/.local/lib/python3.10/site-packages/uvicorn/middleware/proxy_headers.py", line 84, in __call__
    return await self.app(scope, receive, send)
  File "/home/ubuntu/.local/lib/python3.10/site-packages/fastapi/applications.py", line 292, in __call__
    await super().__call__(scope, receive, send)
  File "/home/ubuntu/.local/lib/python3.10/site-packages/starlette/applications.py", line 122, in __call__
    await self.middleware_stack(scope, receive, send)
  File "/home/ubuntu/.local/lib/python3.10/site-packages/starlette/middleware/errors.py", line 184, in __call__
    raise exc
  File "/home/ubuntu/.local/lib/python3.10/site-packages/starlette/middleware/errors.py", line 162, in __call__
    await self.app(scope, receive, _send)
  File "/home/ubuntu/.local/lib/python3.10/site-packages/starlette/middleware/base.py", line 108, in __call__
    response = await self.dispatch_func(request, call_next)
  File "/home/ubuntu/LawGPT_api/main.py", line 123, in auth_middleware
    raise HTTPException(status_code=401, detail="Not authenticated")
fastapi.exceptions.HTTPException
INFO:     127.0.0.1:49682 - "GET /.env HTTP/1.0" 500 Internal Server Error
ERROR:    Exception in ASGI application
Traceback (most recent call last):
  File "/home/ubuntu/.local/lib/python3.10/site-packages/uvicorn/protocols/http/httptools_impl.py", line 426, in run_asgi
    result = await app(  # type: ignore[func-returns-value]
  File "/home/ubuntu/.local/lib/python3.10/site-packages/uvicorn/middleware/proxy_headers.py", line 84, in __call__
    return await self.app(scope, receive, send)
  File "/home/ubuntu/.local/lib/python3.10/site-packages/fastapi/applications.py", line 292, in __call__
    await super().__call__(scope, receive, send)
  File "/home/ubuntu/.local/lib/python3.10/site-packages/starlette/applications.py", line 122, in __call__
    await self.middleware_stack(scope, receive, send)
  File "/home/ubuntu/.local/lib/python3.10/site-packages/starlette/middleware/errors.py", line 184, in __call__
    raise exc
  File "/home/ubuntu/.local/lib/python3.10/site-packages/starlette/middleware/errors.py", line 162, in __call__
    await self.app(scope, receive, _send)
  File "/home/ubuntu/.local/lib/python3.10/site-packages/starlette/middleware/base.py", line 108, in __call__
    response = await self.dispatch_func(request, call_next)
  File "/home/ubuntu/LawGPT_api/main.py", line 123, in auth_middleware
    raise HTTPException(status_code=401, detail="Not authenticated")
fastapi.exceptions.HTTPException
INFO:     127.0.0.1:49686 - "POST / HTTP/1.0" 500 Internal Server Error
ERROR:    Exception in ASGI application
Traceback (most recent call last):
  File "/home/ubuntu/.local/lib/python3.10/site-packages/uvicorn/protocols/http/httptools_impl.py", line 426, in run_asgi
    result = await app(  # type: ignore[func-returns-value]
  File "/home/ubuntu/.local/lib/python3.10/site-packages/uvicorn/middleware/proxy_headers.py", line 84, in __call__
    return await self.app(scope, receive, send)
  File "/home/ubuntu/.local/lib/python3.10/site-packages/fastapi/applications.py", line 292, in __call__
    await super().__call__(scope, receive, send)
  File "/home/ubuntu/.local/lib/python3.10/site-packages/starlette/applications.py", line 122, in __call__
    await self.middleware_stack(scope, receive, send)
  File "/home/ubuntu/.local/lib/python3.10/site-packages/starlette/middleware/errors.py", line 184, in __call__
    raise exc
  File "/home/ubuntu/.local/lib/python3.10/site-packages/starlette/middleware/errors.py", line 162, in __call__
    await self.app(scope, receive, _send)
  File "/home/ubuntu/.local/lib/python3.10/site-packages/starlette/middleware/base.py", line 108, in __call__
    response = await self.dispatch_func(request, call_next)
  File "/home/ubuntu/LawGPT_api/main.py", line 123, in auth_middleware
    raise HTTPException(status_code=401, detail="Not authenticated")
fastapi.exceptions.HTTPException
{'_id': ObjectId('6555e651ba939ed5811894de'), 'name': 'string', 'email': 'user2@example.com', 'password': 'string2'}
INFO:     127.0.0.1:38612 - "POST /signin HTTP/1.0" 200 OK
{'_id': ObjectId('6555e651ba939ed5811894de'), 'name': 'string', 'email': 'user2@example.com', 'password': 'string2'}
INFO:     127.0.0.1:38618 - "POST /signin HTTP/1.0" 200 OK
INFO:     127.0.0.1:57038 - "GET /userid HTTP/1.0" 200 OK
INFO:     127.0.0.1:33668 - "GET /SessionId HTTP/1.0" 200 OK
INFO:     127.0.0.1:55396 - "GET /history HTTP/1.0" 200 OK
INFO:     127.0.0.1:41210 - "GET /op/9_md/9/9/9/9/9 HTTP/1.0" 500 Internal Server Error
ERROR:    Exception in ASGI application
Traceback (most recent call last):
  File "/home/ubuntu/.local/lib/python3.10/site-packages/uvicorn/protocols/http/httptools_impl.py", line 426, in run_asgi
    result = await app(  # type: ignore[func-returns-value]
  File "/home/ubuntu/.local/lib/python3.10/site-packages/uvicorn/middleware/proxy_headers.py", line 84, in __call__
    return await self.app(scope, receive, send)
  File "/home/ubuntu/.local/lib/python3.10/site-packages/fastapi/applications.py", line 292, in __call__
    await super().__call__(scope, receive, send)
  File "/home/ubuntu/.local/lib/python3.10/site-packages/starlette/applications.py", line 122, in __call__
    await self.middleware_stack(scope, receive, send)
  File "/home/ubuntu/.local/lib/python3.10/site-packages/starlette/middleware/errors.py", line 184, in __call__
    raise exc
  File "/home/ubuntu/.local/lib/python3.10/site-packages/starlette/middleware/errors.py", line 162, in __call__
    await self.app(scope, receive, _send)
  File "/home/ubuntu/.local/lib/python3.10/site-packages/starlette/middleware/base.py", line 108, in __call__
    response = await self.dispatch_func(request, call_next)
  File "/home/ubuntu/LawGPT_api/main.py", line 123, in auth_middleware
    raise HTTPException(status_code=401, detail="Not authenticated")
fastapi.exceptions.HTTPException
INFO:     127.0.0.1:59206 - "GET /SessionId HTTP/1.0" 200 OK
INFO:     127.0.0.1:49550 - "GET /SessionId HTTP/1.0" 200 OK
INFO:     127.0.0.1:55760 - "GET /.env HTTP/1.0" 500 Internal Server Error
ERROR:    Exception in ASGI application
Traceback (most recent call last):
  File "/home/ubuntu/.local/lib/python3.10/site-packages/uvicorn/protocols/http/httptools_impl.py", line 426, in run_asgi
    result = await app(  # type: ignore[func-returns-value]
  File "/home/ubuntu/.local/lib/python3.10/site-packages/uvicorn/middleware/proxy_headers.py", line 84, in __call__
    return await self.app(scope, receive, send)
  File "/home/ubuntu/.local/lib/python3.10/site-packages/fastapi/applications.py", line 292, in __call__
    await super().__call__(scope, receive, send)
  File "/home/ubuntu/.local/lib/python3.10/site-packages/starlette/applications.py", line 122, in __call__
    await self.middleware_stack(scope, receive, send)
  File "/home/ubuntu/.local/lib/python3.10/site-packages/starlette/middleware/errors.py", line 184, in __call__
    raise exc
  File "/home/ubuntu/.local/lib/python3.10/site-packages/starlette/middleware/errors.py", line 162, in __call__
    await self.app(scope, receive, _send)
  File "/home/ubuntu/.local/lib/python3.10/site-packages/starlette/middleware/base.py", line 108, in __call__
    response = await self.dispatch_func(request, call_next)
  File "/home/ubuntu/LawGPT_api/main.py", line 123, in auth_middleware
    raise HTTPException(status_code=401, detail="Not authenticated")
fastapi.exceptions.HTTPException
INFO:     127.0.0.1:42766 - "HEAD /Core/Skin/Login.aspx HTTP/1.0" 500 Internal Server Error
ERROR:    Exception in ASGI application
Traceback (most recent call last):
  File "/home/ubuntu/.local/lib/python3.10/site-packages/uvicorn/protocols/http/httptools_impl.py", line 426, in run_asgi
    result = await app(  # type: ignore[func-returns-value]
  File "/home/ubuntu/.local/lib/python3.10/site-packages/uvicorn/middleware/proxy_headers.py", line 84, in __call__
    return await self.app(scope, receive, send)
  File "/home/ubuntu/.local/lib/python3.10/site-packages/fastapi/applications.py", line 292, in __call__
    await super().__call__(scope, receive, send)
  File "/home/ubuntu/.local/lib/python3.10/site-packages/starlette/applications.py", line 122, in __call__
    await self.middleware_stack(scope, receive, send)
  File "/home/ubuntu/.local/lib/python3.10/site-packages/starlette/middleware/errors.py", line 184, in __call__
    raise exc
  File "/home/ubuntu/.local/lib/python3.10/site-packages/starlette/middleware/errors.py", line 162, in __call__
    await self.app(scope, receive, _send)
  File "/home/ubuntu/.local/lib/python3.10/site-packages/starlette/middleware/base.py", line 108, in __call__
    response = await self.dispatch_func(request, call_next)
  File "/home/ubuntu/LawGPT_api/main.py", line 123, in auth_middleware
    raise HTTPException(status_code=401, detail="Not authenticated")
fastapi.exceptions.HTTPException
INFO:     127.0.0.1:52130 - "GET /.env HTTP/1.0" 500 Internal Server Error
ERROR:    Exception in ASGI application
Traceback (most recent call last):
  File "/home/ubuntu/.local/lib/python3.10/site-packages/uvicorn/protocols/http/httptools_impl.py", line 426, in run_asgi
    result = await app(  # type: ignore[func-returns-value]
  File "/home/ubuntu/.local/lib/python3.10/site-packages/uvicorn/middleware/proxy_headers.py", line 84, in __call__
    return await self.app(scope, receive, send)
  File "/home/ubuntu/.local/lib/python3.10/site-packages/fastapi/applications.py", line 292, in __call__
    await super().__call__(scope, receive, send)
  File "/home/ubuntu/.local/lib/python3.10/site-packages/starlette/applications.py", line 122, in __call__
    await self.middleware_stack(scope, receive, send)
  File "/home/ubuntu/.local/lib/python3.10/site-packages/starlette/middleware/errors.py", line 184, in __call__
    raise exc
  File "/home/ubuntu/.local/lib/python3.10/site-packages/starlette/middleware/errors.py", line 162, in __call__
    await self.app(scope, receive, _send)
  File "/home/ubuntu/.local/lib/python3.10/site-packages/starlette/middleware/base.py", line 108, in __call__
    response = await self.dispatch_func(request, call_next)
  File "/home/ubuntu/LawGPT_api/main.py", line 123, in auth_middleware
    raise HTTPException(status_code=401, detail="Not authenticated")
fastapi.exceptions.HTTPException
INFO:     127.0.0.1:39252 - "GET /.env HTTP/1.0" 500 Internal Server Error
ERROR:    Exception in ASGI application
Traceback (most recent call last):
  File "/home/ubuntu/.local/lib/python3.10/site-packages/uvicorn/protocols/http/httptools_impl.py", line 426, in run_asgi
    result = await app(  # type: ignore[func-returns-value]
  File "/home/ubuntu/.local/lib/python3.10/site-packages/uvicorn/middleware/proxy_headers.py", line 84, in __call__
    return await self.app(scope, receive, send)
  File "/home/ubuntu/.local/lib/python3.10/site-packages/fastapi/applications.py", line 292, in __call__
    await super().__call__(scope, receive, send)
  File "/home/ubuntu/.local/lib/python3.10/site-packages/starlette/applications.py", line 122, in __call__
    await self.middleware_stack(scope, receive, send)
  File "/home/ubuntu/.local/lib/python3.10/site-packages/starlette/middleware/errors.py", line 184, in __call__
    raise exc
  File "/home/ubuntu/.local/lib/python3.10/site-packages/starlette/middleware/errors.py", line 162, in __call__
    await self.app(scope, receive, _send)
  File "/home/ubuntu/.local/lib/python3.10/site-packages/starlette/middleware/base.py", line 108, in __call__
    response = await self.dispatch_func(request, call_next)
  File "/home/ubuntu/LawGPT_api/main.py", line 123, in auth_middleware
    raise HTTPException(status_code=401, detail="Not authenticated")
fastapi.exceptions.HTTPException
INFO:     127.0.0.1:39268 - "POST / HTTP/1.0" 500 Internal Server Error
ERROR:    Exception in ASGI application
Traceback (most recent call last):
  File "/home/ubuntu/.local/lib/python3.10/site-packages/uvicorn/protocols/http/httptools_impl.py", line 426, in run_asgi
    result = await app(  # type: ignore[func-returns-value]
  File "/home/ubuntu/.local/lib/python3.10/site-packages/uvicorn/middleware/proxy_headers.py", line 84, in __call__
    return await self.app(scope, receive, send)
  File "/home/ubuntu/.local/lib/python3.10/site-packages/fastapi/applications.py", line 292, in __call__
    await super().__call__(scope, receive, send)
  File "/home/ubuntu/.local/lib/python3.10/site-packages/starlette/applications.py", line 122, in __call__
    await self.middleware_stack(scope, receive, send)
  File "/home/ubuntu/.local/lib/python3.10/site-packages/starlette/middleware/errors.py", line 184, in __call__
    raise exc
  File "/home/ubuntu/.local/lib/python3.10/site-packages/starlette/middleware/errors.py", line 162, in __call__
    await self.app(scope, receive, _send)
  File "/home/ubuntu/.local/lib/python3.10/site-packages/starlette/middleware/base.py", line 108, in __call__
    response = await self.dispatch_func(request, call_next)
  File "/home/ubuntu/LawGPT_api/main.py", line 123, in auth_middleware
    raise HTTPException(status_code=401, detail="Not authenticated")
fastapi.exceptions.HTTPException
INFO:     127.0.0.1:41328 - "GET /Temporary_Listen_Addresses HTTP/1.0" 500 Internal Server Error
ERROR:    Exception in ASGI application
Traceback (most recent call last):
  File "/home/ubuntu/.local/lib/python3.10/site-packages/uvicorn/protocols/http/httptools_impl.py", line 426, in run_asgi
    result = await app(  # type: ignore[func-returns-value]
  File "/home/ubuntu/.local/lib/python3.10/site-packages/uvicorn/middleware/proxy_headers.py", line 84, in __call__
    return await self.app(scope, receive, send)
  File "/home/ubuntu/.local/lib/python3.10/site-packages/fastapi/applications.py", line 292, in __call__
    await super().__call__(scope, receive, send)
  File "/home/ubuntu/.local/lib/python3.10/site-packages/starlette/applications.py", line 122, in __call__
    await self.middleware_stack(scope, receive, send)
  File "/home/ubuntu/.local/lib/python3.10/site-packages/starlette/middleware/errors.py", line 184, in __call__
    raise exc
  File "/home/ubuntu/.local/lib/python3.10/site-packages/starlette/middleware/errors.py", line 162, in __call__
    await self.app(scope, receive, _send)
  File "/home/ubuntu/.local/lib/python3.10/site-packages/starlette/middleware/base.py", line 108, in __call__
    response = await self.dispatch_func(request, call_next)
  File "/home/ubuntu/LawGPT_api/main.py", line 123, in auth_middleware
    raise HTTPException(status_code=401, detail="Not authenticated")
fastapi.exceptions.HTTPException
INFO:     127.0.0.1:41334 - "GET /Pages/log/ HTTP/1.0" 500 Internal Server Error
ERROR:    Exception in ASGI application
Traceback (most recent call last):
  File "/home/ubuntu/.local/lib/python3.10/site-packages/uvicorn/protocols/http/httptools_impl.py", line 426, in run_asgi
    result = await app(  # type: ignore[func-returns-value]
  File "/home/ubuntu/.local/lib/python3.10/site-packages/uvicorn/middleware/proxy_headers.py", line 84, in __call__
    return await self.app(scope, receive, send)
  File "/home/ubuntu/.local/lib/python3.10/site-packages/fastapi/applications.py", line 292, in __call__
    await super().__call__(scope, receive, send)
  File "/home/ubuntu/.local/lib/python3.10/site-packages/starlette/applications.py", line 122, in __call__
    await self.middleware_stack(scope, receive, send)
  File "/home/ubuntu/.local/lib/python3.10/site-packages/starlette/middleware/errors.py", line 184, in __call__
    raise exc
  File "/home/ubuntu/.local/lib/python3.10/site-packages/starlette/middleware/errors.py", line 162, in __call__
    await self.app(scope, receive, _send)
  File "/home/ubuntu/.local/lib/python3.10/site-packages/starlette/middleware/base.py", line 108, in __call__
    response = await self.dispatch_func(request, call_next)
  File "/home/ubuntu/LawGPT_api/main.py", line 123, in auth_middleware
    raise HTTPException(status_code=401, detail="Not authenticated")
fastapi.exceptions.HTTPException
INFO:     127.0.0.1:55510 - "GET /.env HTTP/1.0" 500 Internal Server Error
ERROR:    Exception in ASGI application
Traceback (most recent call last):
  File "/home/ubuntu/.local/lib/python3.10/site-packages/uvicorn/protocols/http/httptools_impl.py", line 426, in run_asgi
    result = await app(  # type: ignore[func-returns-value]
  File "/home/ubuntu/.local/lib/python3.10/site-packages/uvicorn/middleware/proxy_headers.py", line 84, in __call__
    return await self.app(scope, receive, send)
  File "/home/ubuntu/.local/lib/python3.10/site-packages/fastapi/applications.py", line 292, in __call__
    await super().__call__(scope, receive, send)
  File "/home/ubuntu/.local/lib/python3.10/site-packages/starlette/applications.py", line 122, in __call__
    await self.middleware_stack(scope, receive, send)
  File "/home/ubuntu/.local/lib/python3.10/site-packages/starlette/middleware/errors.py", line 184, in __call__
    raise exc
  File "/home/ubuntu/.local/lib/python3.10/site-packages/starlette/middleware/errors.py", line 162, in __call__
    await self.app(scope, receive, _send)
  File "/home/ubuntu/.local/lib/python3.10/site-packages/starlette/middleware/base.py", line 108, in __call__
    response = await self.dispatch_func(request, call_next)
  File "/home/ubuntu/LawGPT_api/main.py", line 123, in auth_middleware
    raise HTTPException(status_code=401, detail="Not authenticated")
fastapi.exceptions.HTTPException
INFO:     127.0.0.1:55526 - "POST / HTTP/1.0" 500 Internal Server Error
ERROR:    Exception in ASGI application
Traceback (most recent call last):
  File "/home/ubuntu/.local/lib/python3.10/site-packages/uvicorn/protocols/http/httptools_impl.py", line 426, in run_asgi
    result = await app(  # type: ignore[func-returns-value]
  File "/home/ubuntu/.local/lib/python3.10/site-packages/uvicorn/middleware/proxy_headers.py", line 84, in __call__
    return await self.app(scope, receive, send)
  File "/home/ubuntu/.local/lib/python3.10/site-packages/fastapi/applications.py", line 292, in __call__
    await super().__call__(scope, receive, send)
  File "/home/ubuntu/.local/lib/python3.10/site-packages/starlette/applications.py", line 122, in __call__
    await self.middleware_stack(scope, receive, send)
  File "/home/ubuntu/.local/lib/python3.10/site-packages/starlette/middleware/errors.py", line 184, in __call__
    raise exc
  File "/home/ubuntu/.local/lib/python3.10/site-packages/starlette/middleware/errors.py", line 162, in __call__
    await self.app(scope, receive, _send)
  File "/home/ubuntu/.local/lib/python3.10/site-packages/starlette/middleware/base.py", line 108, in __call__
    response = await self.dispatch_func(request, call_next)
  File "/home/ubuntu/LawGPT_api/main.py", line 123, in auth_middleware
    raise HTTPException(status_code=401, detail="Not authenticated")
fastapi.exceptions.HTTPException
INFO:     Shutting down
INFO:     Waiting for application shutdown.
INFO:     Application shutdown complete.
INFO:     Finished server process [60680]
INFO:     Started server process [61967]
INFO:     Waiting for application startup.
INFO:     Application startup complete.
INFO:     Uvicorn running on http://127.0.0.1:8000 (Press CTRL+C to quit)
INFO:     127.0.0.1:54488 - "GET /docs HTTP/1.0" 200 OK
INFO:     127.0.0.1:54504 - "GET /openapi.json HTTP/1.0" 200 OK
INFO:     127.0.0.1:56002 - "GET /SessionId HTTP/1.0" 500 Internal Server Error
ERROR:    Exception in ASGI application
Traceback (most recent call last):
  File "/home/ubuntu/.local/lib/python3.10/site-packages/anyio/streams/memory.py", line 98, in receive
    return self.receive_nowait()
  File "/home/ubuntu/.local/lib/python3.10/site-packages/anyio/streams/memory.py", line 93, in receive_nowait
    raise WouldBlock
anyio.WouldBlock

During handling of the above exception, another exception occurred:

Traceback (most recent call last):
  File "/home/ubuntu/.local/lib/python3.10/site-packages/starlette/middleware/base.py", line 78, in call_next
    message = await recv_stream.receive()
  File "/home/ubuntu/.local/lib/python3.10/site-packages/anyio/streams/memory.py", line 118, in receive
    raise EndOfStream
anyio.EndOfStream

During handling of the above exception, another exception occurred:

Traceback (most recent call last):
  File "/home/ubuntu/.local/lib/python3.10/site-packages/uvicorn/protocols/http/httptools_impl.py", line 426, in run_asgi
    result = await app(  # type: ignore[func-returns-value]
  File "/home/ubuntu/.local/lib/python3.10/site-packages/uvicorn/middleware/proxy_headers.py", line 84, in __call__
    return await self.app(scope, receive, send)
  File "/home/ubuntu/.local/lib/python3.10/site-packages/fastapi/applications.py", line 292, in __call__
    await super().__call__(scope, receive, send)
  File "/home/ubuntu/.local/lib/python3.10/site-packages/starlette/applications.py", line 122, in __call__
    await self.middleware_stack(scope, receive, send)
  File "/home/ubuntu/.local/lib/python3.10/site-packages/starlette/middleware/errors.py", line 184, in __call__
    raise exc
  File "/home/ubuntu/.local/lib/python3.10/site-packages/starlette/middleware/errors.py", line 162, in __call__
    await self.app(scope, receive, _send)
  File "/home/ubuntu/.local/lib/python3.10/site-packages/starlette/middleware/base.py", line 108, in __call__
    response = await self.dispatch_func(request, call_next)
  File "/home/ubuntu/LawGPT_api/main.py", line 133, in auth_middleware
    response = await call_next(request)
  File "/home/ubuntu/.local/lib/python3.10/site-packages/starlette/middleware/base.py", line 84, in call_next
    raise app_exc
  File "/home/ubuntu/.local/lib/python3.10/site-packages/starlette/middleware/base.py", line 70, in coro
    await self.app(scope, receive_or_disconnect, send_no_error)
  File "/home/ubuntu/.local/lib/python3.10/site-packages/starlette/middleware/exceptions.py", line 79, in __call__
    raise exc
  File "/home/ubuntu/.local/lib/python3.10/site-packages/starlette/middleware/exceptions.py", line 68, in __call__
    await self.app(scope, receive, sender)
  File "/home/ubuntu/.local/lib/python3.10/site-packages/fastapi/middleware/asyncexitstack.py", line 20, in __call__
    raise e
  File "/home/ubuntu/.local/lib/python3.10/site-packages/fastapi/middleware/asyncexitstack.py", line 17, in __call__
    await self.app(scope, receive, send)
  File "/home/ubuntu/.local/lib/python3.10/site-packages/starlette/routing.py", line 718, in __call__
    await route.handle(scope, receive, send)
  File "/home/ubuntu/.local/lib/python3.10/site-packages/starlette/routing.py", line 276, in handle
    await self.app(scope, receive, send)
  File "/home/ubuntu/.local/lib/python3.10/site-packages/starlette/routing.py", line 66, in app
    response = await func(request)
  File "/home/ubuntu/.local/lib/python3.10/site-packages/fastapi/routing.py", line 273, in app
    raw_response = await run_endpoint_function(
  File "/home/ubuntu/.local/lib/python3.10/site-packages/fastapi/routing.py", line 190, in run_endpoint_function
    return await dependant.call(**values)
  File "/home/ubuntu/LawGPT_api/main.py", line 75, in sessionid
    return get_sessionid(user_id, chat_history_collection)
  File "/home/ubuntu/LawGPT_api/utilities.py", line 92, in get_sessionid
    return json.dumps(list(collection.aggregate(pipeline)))
  File "/home/ubuntu/.local/lib/python3.10/site-packages/pymongo/collection.py", line 2722, in aggregate
    return self._aggregate(
  File "/home/ubuntu/.local/lib/python3.10/site-packages/pymongo/_csot.py", line 108, in csot_wrapper
    return func(self, *args, **kwargs)
  File "/home/ubuntu/.local/lib/python3.10/site-packages/pymongo/collection.py", line 2629, in _aggregate
    return self.__database.client._retryable_read(
  File "/home/ubuntu/.local/lib/python3.10/site-packages/pymongo/_csot.py", line 108, in csot_wrapper
    return func(self, *args, **kwargs)
  File "/home/ubuntu/.local/lib/python3.10/site-packages/pymongo/mongo_client.py", line 1535, in _retryable_read
    return func(session, server, conn, read_pref)
  File "/home/ubuntu/.local/lib/python3.10/site-packages/pymongo/aggregation.py", line 164, in get_cursor
    result = conn.command(
  File "/home/ubuntu/.local/lib/python3.10/site-packages/pymongo/helpers.py", line 315, in inner
    return func(*args, **kwargs)
  File "/home/ubuntu/.local/lib/python3.10/site-packages/pymongo/pool.py", line 960, in command
    self._raise_connection_failure(error)
  File "/home/ubuntu/.local/lib/python3.10/site-packages/pymongo/pool.py", line 932, in command
    return command(
  File "/home/ubuntu/.local/lib/python3.10/site-packages/pymongo/network.py", line 150, in command
    request_id, msg, size, max_doc_size = message._op_msg(
  File "/home/ubuntu/.local/lib/python3.10/site-packages/pymongo/message.py", line 765, in _op_msg
    return _op_msg_uncompressed(flags, command, identifier, docs, opts)
bson.errors.InvalidDocument: cannot encode object: for_userid(userid='6555e651ba939ed5811894de'), of type: <class 'Classes.for_userid'>
INFO:     127.0.0.1:50128 - "GET /docs HTTP/1.0" 200 OK
INFO:     127.0.0.1:50140 - "GET /openapi.json HTTP/1.0" 200 OK
INFO:     127.0.0.1:44278 - "GET /history HTTP/1.0" 200 OK
INFO:     127.0.0.1:46342 - "GET /userid HTTP/1.0" 200 OK
INFO:     127.0.0.1:41582 - "GET /history HTTP/1.0" 200 OK
INFO:     127.0.0.1:42718 - "GET /SessionId HTTP/1.0" 500 Internal Server Error
ERROR:    Exception in ASGI application
Traceback (most recent call last):
  File "/home/ubuntu/.local/lib/python3.10/site-packages/anyio/streams/memory.py", line 98, in receive
    return self.receive_nowait()
  File "/home/ubuntu/.local/lib/python3.10/site-packages/anyio/streams/memory.py", line 93, in receive_nowait
    raise WouldBlock
anyio.WouldBlock

During handling of the above exception, another exception occurred:

Traceback (most recent call last):
  File "/home/ubuntu/.local/lib/python3.10/site-packages/starlette/middleware/base.py", line 78, in call_next
    message = await recv_stream.receive()
  File "/home/ubuntu/.local/lib/python3.10/site-packages/anyio/streams/memory.py", line 118, in receive
    raise EndOfStream
anyio.EndOfStream

During handling of the above exception, another exception occurred:

Traceback (most recent call last):
  File "/home/ubuntu/.local/lib/python3.10/site-packages/uvicorn/protocols/http/httptools_impl.py", line 426, in run_asgi
    result = await app(  # type: ignore[func-returns-value]
  File "/home/ubuntu/.local/lib/python3.10/site-packages/uvicorn/middleware/proxy_headers.py", line 84, in __call__
    return await self.app(scope, receive, send)
  File "/home/ubuntu/.local/lib/python3.10/site-packages/fastapi/applications.py", line 292, in __call__
    await super().__call__(scope, receive, send)
  File "/home/ubuntu/.local/lib/python3.10/site-packages/starlette/applications.py", line 122, in __call__
    await self.middleware_stack(scope, receive, send)
  File "/home/ubuntu/.local/lib/python3.10/site-packages/starlette/middleware/errors.py", line 184, in __call__
    raise exc
  File "/home/ubuntu/.local/lib/python3.10/site-packages/starlette/middleware/errors.py", line 162, in __call__
    await self.app(scope, receive, _send)
  File "/home/ubuntu/.local/lib/python3.10/site-packages/starlette/middleware/base.py", line 108, in __call__
    response = await self.dispatch_func(request, call_next)
  File "/home/ubuntu/LawGPT_api/main.py", line 133, in auth_middleware
    response = await call_next(request)
  File "/home/ubuntu/.local/lib/python3.10/site-packages/starlette/middleware/base.py", line 84, in call_next
    raise app_exc
  File "/home/ubuntu/.local/lib/python3.10/site-packages/starlette/middleware/base.py", line 70, in coro
    await self.app(scope, receive_or_disconnect, send_no_error)
  File "/home/ubuntu/.local/lib/python3.10/site-packages/starlette/middleware/exceptions.py", line 79, in __call__
    raise exc
  File "/home/ubuntu/.local/lib/python3.10/site-packages/starlette/middleware/exceptions.py", line 68, in __call__
    await self.app(scope, receive, sender)
  File "/home/ubuntu/.local/lib/python3.10/site-packages/fastapi/middleware/asyncexitstack.py", line 20, in __call__
    raise e
  File "/home/ubuntu/.local/lib/python3.10/site-packages/fastapi/middleware/asyncexitstack.py", line 17, in __call__
    await self.app(scope, receive, send)
  File "/home/ubuntu/.local/lib/python3.10/site-packages/starlette/routing.py", line 718, in __call__
    await route.handle(scope, receive, send)
  File "/home/ubuntu/.local/lib/python3.10/site-packages/starlette/routing.py", line 276, in handle
    await self.app(scope, receive, send)
  File "/home/ubuntu/.local/lib/python3.10/site-packages/starlette/routing.py", line 66, in app
    response = await func(request)
  File "/home/ubuntu/.local/lib/python3.10/site-packages/fastapi/routing.py", line 273, in app
    raw_response = await run_endpoint_function(
  File "/home/ubuntu/.local/lib/python3.10/site-packages/fastapi/routing.py", line 190, in run_endpoint_function
    return await dependant.call(**values)
  File "/home/ubuntu/LawGPT_api/main.py", line 75, in sessionid
    return get_sessionid(user_id, chat_history_collection)
  File "/home/ubuntu/LawGPT_api/utilities.py", line 92, in get_sessionid
    return json.dumps(list(collection.aggregate(pipeline)))
  File "/home/ubuntu/.local/lib/python3.10/site-packages/pymongo/collection.py", line 2722, in aggregate
    return self._aggregate(
  File "/home/ubuntu/.local/lib/python3.10/site-packages/pymongo/_csot.py", line 108, in csot_wrapper
    return func(self, *args, **kwargs)
  File "/home/ubuntu/.local/lib/python3.10/site-packages/pymongo/collection.py", line 2629, in _aggregate
    return self.__database.client._retryable_read(
  File "/home/ubuntu/.local/lib/python3.10/site-packages/pymongo/_csot.py", line 108, in csot_wrapper
    return func(self, *args, **kwargs)
  File "/home/ubuntu/.local/lib/python3.10/site-packages/pymongo/mongo_client.py", line 1535, in _retryable_read
    return func(session, server, conn, read_pref)
  File "/home/ubuntu/.local/lib/python3.10/site-packages/pymongo/aggregation.py", line 164, in get_cursor
    result = conn.command(
  File "/home/ubuntu/.local/lib/python3.10/site-packages/pymongo/helpers.py", line 315, in inner
    return func(*args, **kwargs)
  File "/home/ubuntu/.local/lib/python3.10/site-packages/pymongo/pool.py", line 960, in command
    self._raise_connection_failure(error)
  File "/home/ubuntu/.local/lib/python3.10/site-packages/pymongo/pool.py", line 932, in command
    return command(
  File "/home/ubuntu/.local/lib/python3.10/site-packages/pymongo/network.py", line 150, in command
    request_id, msg, size, max_doc_size = message._op_msg(
  File "/home/ubuntu/.local/lib/python3.10/site-packages/pymongo/message.py", line 765, in _op_msg
    return _op_msg_uncompressed(flags, command, identifier, docs, opts)
bson.errors.InvalidDocument: cannot encode object: for_userid(userid='6555e651ba939ed5811894de'), of type: <class 'Classes.for_userid'>
INFO:     Shutting down
INFO:     Waiting for application shutdown.
INFO:     Application shutdown complete.
INFO:     Finished server process [61967]
