python3: can't open file '/home/ubuntu/LawGPT_api/uvicorn': [Errno 2] No such file or directory
INFO:     Started server process [60680]
INFO:     Waiting for application startup.
INFO:     Application startup complete.
INFO:     Uvicorn running on http://127.0.0.1:8000 (Press CTRL+C to quit)
INFO:     127.0.0.1:34946 - "GET /docs HTTP/1.0" 200 OK
INFO:     127.0.0.1:34950 - "GET /openapi.json HTTP/1.0" 200 OK
{'_id': ObjectId('6555e651ba939ed5811894de'), 'name': 'string', 'email': 'user2@example.com', 'password': 'string2'}
INFO:     127.0.0.1:35792 - "POST /signin HTTP/1.0" 200 OK
INFO:     127.0.0.1:56326 - "GET /userid HTTP/1.0" 500 Internal Server Error
ERROR:    Exception in ASGI application
Traceback (most recent call last):
  File "/home/ubuntu/.local/lib/python3.10/site-packages/uvicorn/protocols/http/httptools_impl.py", line 426, in run_asgi
    result = await app(  # type: ignore[func-returns-value]
  File "/home/ubuntu/.local/lib/python3.10/site-packages/uvicorn/middleware/proxy_headers.py", line 84, in __call__
    return await self.app(scope, receive, send)
  File "/home/ubuntu/.local/lib/python3.10/site-packages/fastapi/applications.py", line 292, in __call__
    await super().__call__(scope, receive, send)
  File "/home/ubuntu/.local/lib/python3.10/site-packages/starlette/applications.py", line 122, in __call__
    await self.middleware_stack(scope, receive, send)
  File "/home/ubuntu/.local/lib/python3.10/site-packages/starlette/middleware/errors.py", line 184, in __call__
    raise exc
  File "/home/ubuntu/.local/lib/python3.10/site-packages/starlette/middleware/errors.py", line 162, in __call__
    await self.app(scope, receive, _send)
  File "/home/ubuntu/.local/lib/python3.10/site-packages/starlette/middleware/base.py", line 108, in __call__
    response = await self.dispatch_func(request, call_next)
  File "/home/ubuntu/LawGPT_api/main.py", line 123, in auth_middleware
    raise HTTPException(status_code=401, detail="Not authenticated")
fastapi.exceptions.HTTPException
{'_id': ObjectId('6555e651ba939ed5811894de'), 'name': 'string', 'email': 'user2@example.com', 'password': 'string2'}
INFO:     127.0.0.1:52662 - "POST /signin HTTP/1.0" 200 OK
INFO:     127.0.0.1:49756 - "GET /userid HTTP/1.0" 200 OK
INFO:     127.0.0.1:44400 - "GET /SessionId HTTP/1.0" 200 OK
INFO:     127.0.0.1:57576 - "GET /history HTTP/1.0" 200 OK
INFO:     127.0.0.1:60818 - "GET /docs HTTP/1.0" 200 OK
INFO:     127.0.0.1:60830 - "GET /openapi.json HTTP/1.0" 200 OK
INFO:     127.0.0.1:40894 - "GET / HTTP/1.0" 500 Internal Server Error
ERROR:    Exception in ASGI application
Traceback (most recent call last):
  File "/home/ubuntu/.local/lib/python3.10/site-packages/uvicorn/protocols/http/httptools_impl.py", line 426, in run_asgi
    result = await app(  # type: ignore[func-returns-value]
  File "/home/ubuntu/.local/lib/python3.10/site-packages/uvicorn/middleware/proxy_headers.py", line 84, in __call__
    return await self.app(scope, receive, send)
  File "/home/ubuntu/.local/lib/python3.10/site-packages/fastapi/applications.py", line 292, in __call__
    await super().__call__(scope, receive, send)
  File "/home/ubuntu/.local/lib/python3.10/site-packages/starlette/applications.py", line 122, in __call__
    await self.middleware_stack(scope, receive, send)
  File "/home/ubuntu/.local/lib/python3.10/site-packages/starlette/middleware/errors.py", line 184, in __call__
    raise exc
  File "/home/ubuntu/.local/lib/python3.10/site-packages/starlette/middleware/errors.py", line 162, in __call__
    await self.app(scope, receive, _send)
  File "/home/ubuntu/.local/lib/python3.10/site-packages/starlette/middleware/base.py", line 108, in __call__
    response = await self.dispatch_func(request, call_next)
  File "/home/ubuntu/LawGPT_api/main.py", line 123, in auth_middleware
    raise HTTPException(status_code=401, detail="Not authenticated")
fastapi.exceptions.HTTPException
INFO:     127.0.0.1:49464 - "GET /.env HTTP/1.0" 500 Internal Server Error
ERROR:    Exception in ASGI application
Traceback (most recent call last):
  File "/home/ubuntu/.local/lib/python3.10/site-packages/uvicorn/protocols/http/httptools_impl.py", line 426, in run_asgi
    result = await app(  # type: ignore[func-returns-value]
  File "/home/ubuntu/.local/lib/python3.10/site-packages/uvicorn/middleware/proxy_headers.py", line 84, in __call__
    return await self.app(scope, receive, send)
  File "/home/ubuntu/.local/lib/python3.10/site-packages/fastapi/applications.py", line 292, in __call__
    await super().__call__(scope, receive, send)
  File "/home/ubuntu/.local/lib/python3.10/site-packages/starlette/applications.py", line 122, in __call__
    await self.middleware_stack(scope, receive, send)
  File "/home/ubuntu/.local/lib/python3.10/site-packages/starlette/middleware/errors.py", line 184, in __call__
    raise exc
  File "/home/ubuntu/.local/lib/python3.10/site-packages/starlette/middleware/errors.py", line 162, in __call__
    await self.app(scope, receive, _send)
  File "/home/ubuntu/.local/lib/python3.10/site-packages/starlette/middleware/base.py", line 108, in __call__
    response = await self.dispatch_func(request, call_next)
  File "/home/ubuntu/LawGPT_api/main.py", line 123, in auth_middleware
    raise HTTPException(status_code=401, detail="Not authenticated")
fastapi.exceptions.HTTPException
INFO:     127.0.0.1:49466 - "POST / HTTP/1.0" 500 Internal Server Error
ERROR:    Exception in ASGI application
Traceback (most recent call last):
  File "/home/ubuntu/.local/lib/python3.10/site-packages/uvicorn/protocols/http/httptools_impl.py", line 426, in run_asgi
    result = await app(  # type: ignore[func-returns-value]
  File "/home/ubuntu/.local/lib/python3.10/site-packages/uvicorn/middleware/proxy_headers.py", line 84, in __call__
    return await self.app(scope, receive, send)
  File "/home/ubuntu/.local/lib/python3.10/site-packages/fastapi/applications.py", line 292, in __call__
    await super().__call__(scope, receive, send)
  File "/home/ubuntu/.local/lib/python3.10/site-packages/starlette/applications.py", line 122, in __call__
    await self.middleware_stack(scope, receive, send)
  File "/home/ubuntu/.local/lib/python3.10/site-packages/starlette/middleware/errors.py", line 184, in __call__
    raise exc
  File "/home/ubuntu/.local/lib/python3.10/site-packages/starlette/middleware/errors.py", line 162, in __call__
    await self.app(scope, receive, _send)
  File "/home/ubuntu/.local/lib/python3.10/site-packages/starlette/middleware/base.py", line 108, in __call__
    response = await self.dispatch_func(request, call_next)
  File "/home/ubuntu/LawGPT_api/main.py", line 123, in auth_middleware
    raise HTTPException(status_code=401, detail="Not authenticated")
fastapi.exceptions.HTTPException
INFO:     127.0.0.1:56962 - "HEAD /Core/Skin/Login.aspx HTTP/1.0" 500 Internal Server Error
ERROR:    Exception in ASGI application
Traceback (most recent call last):
  File "/home/ubuntu/.local/lib/python3.10/site-packages/uvicorn/protocols/http/httptools_impl.py", line 426, in run_asgi
    result = await app(  # type: ignore[func-returns-value]
  File "/home/ubuntu/.local/lib/python3.10/site-packages/uvicorn/middleware/proxy_headers.py", line 84, in __call__
    return await self.app(scope, receive, send)
  File "/home/ubuntu/.local/lib/python3.10/site-packages/fastapi/applications.py", line 292, in __call__
    await super().__call__(scope, receive, send)
  File "/home/ubuntu/.local/lib/python3.10/site-packages/starlette/applications.py", line 122, in __call__
    await self.middleware_stack(scope, receive, send)
  File "/home/ubuntu/.local/lib/python3.10/site-packages/starlette/middleware/errors.py", line 184, in __call__
    raise exc
  File "/home/ubuntu/.local/lib/python3.10/site-packages/starlette/middleware/errors.py", line 162, in __call__
    await self.app(scope, receive, _send)
  File "/home/ubuntu/.local/lib/python3.10/site-packages/starlette/middleware/base.py", line 108, in __call__
    response = await self.dispatch_func(request, call_next)
  File "/home/ubuntu/LawGPT_api/main.py", line 123, in auth_middleware
    raise HTTPException(status_code=401, detail="Not authenticated")
fastapi.exceptions.HTTPException
INFO:     127.0.0.1:51744 - "GET / HTTP/1.0" 500 Internal Server Error
ERROR:    Exception in ASGI application
Traceback (most recent call last):
  File "/home/ubuntu/.local/lib/python3.10/site-packages/uvicorn/protocols/http/httptools_impl.py", line 426, in run_asgi
    result = await app(  # type: ignore[func-returns-value]
  File "/home/ubuntu/.local/lib/python3.10/site-packages/uvicorn/middleware/proxy_headers.py", line 84, in __call__
    return await self.app(scope, receive, send)
  File "/home/ubuntu/.local/lib/python3.10/site-packages/fastapi/applications.py", line 292, in __call__
    await super().__call__(scope, receive, send)
  File "/home/ubuntu/.local/lib/python3.10/site-packages/starlette/applications.py", line 122, in __call__
    await self.middleware_stack(scope, receive, send)
  File "/home/ubuntu/.local/lib/python3.10/site-packages/starlette/middleware/errors.py", line 184, in __call__
    raise exc
  File "/home/ubuntu/.local/lib/python3.10/site-packages/starlette/middleware/errors.py", line 162, in __call__
    await self.app(scope, receive, _send)
  File "/home/ubuntu/.local/lib/python3.10/site-packages/starlette/middleware/base.py", line 108, in __call__
    response = await self.dispatch_func(request, call_next)
  File "/home/ubuntu/LawGPT_api/main.py", line 123, in auth_middleware
    raise HTTPException(status_code=401, detail="Not authenticated")
fastapi.exceptions.HTTPException
INFO:     127.0.0.1:49682 - "GET /.env HTTP/1.0" 500 Internal Server Error
ERROR:    Exception in ASGI application
Traceback (most recent call last):
  File "/home/ubuntu/.local/lib/python3.10/site-packages/uvicorn/protocols/http/httptools_impl.py", line 426, in run_asgi
    result = await app(  # type: ignore[func-returns-value]
  File "/home/ubuntu/.local/lib/python3.10/site-packages/uvicorn/middleware/proxy_headers.py", line 84, in __call__
    return await self.app(scope, receive, send)
  File "/home/ubuntu/.local/lib/python3.10/site-packages/fastapi/applications.py", line 292, in __call__
    await super().__call__(scope, receive, send)
  File "/home/ubuntu/.local/lib/python3.10/site-packages/starlette/applications.py", line 122, in __call__
    await self.middleware_stack(scope, receive, send)
  File "/home/ubuntu/.local/lib/python3.10/site-packages/starlette/middleware/errors.py", line 184, in __call__
    raise exc
  File "/home/ubuntu/.local/lib/python3.10/site-packages/starlette/middleware/errors.py", line 162, in __call__
    await self.app(scope, receive, _send)
  File "/home/ubuntu/.local/lib/python3.10/site-packages/starlette/middleware/base.py", line 108, in __call__
    response = await self.dispatch_func(request, call_next)
  File "/home/ubuntu/LawGPT_api/main.py", line 123, in auth_middleware
    raise HTTPException(status_code=401, detail="Not authenticated")
fastapi.exceptions.HTTPException
INFO:     127.0.0.1:49686 - "POST / HTTP/1.0" 500 Internal Server Error
ERROR:    Exception in ASGI application
Traceback (most recent call last):
  File "/home/ubuntu/.local/lib/python3.10/site-packages/uvicorn/protocols/http/httptools_impl.py", line 426, in run_asgi
    result = await app(  # type: ignore[func-returns-value]
  File "/home/ubuntu/.local/lib/python3.10/site-packages/uvicorn/middleware/proxy_headers.py", line 84, in __call__
    return await self.app(scope, receive, send)
  File "/home/ubuntu/.local/lib/python3.10/site-packages/fastapi/applications.py", line 292, in __call__
    await super().__call__(scope, receive, send)
  File "/home/ubuntu/.local/lib/python3.10/site-packages/starlette/applications.py", line 122, in __call__
    await self.middleware_stack(scope, receive, send)
  File "/home/ubuntu/.local/lib/python3.10/site-packages/starlette/middleware/errors.py", line 184, in __call__
    raise exc
  File "/home/ubuntu/.local/lib/python3.10/site-packages/starlette/middleware/errors.py", line 162, in __call__
    await self.app(scope, receive, _send)
  File "/home/ubuntu/.local/lib/python3.10/site-packages/starlette/middleware/base.py", line 108, in __call__
    response = await self.dispatch_func(request, call_next)
  File "/home/ubuntu/LawGPT_api/main.py", line 123, in auth_middleware
    raise HTTPException(status_code=401, detail="Not authenticated")
fastapi.exceptions.HTTPException
{'_id': ObjectId('6555e651ba939ed5811894de'), 'name': 'string', 'email': 'user2@example.com', 'password': 'string2'}
INFO:     127.0.0.1:38612 - "POST /signin HTTP/1.0" 200 OK
{'_id': ObjectId('6555e651ba939ed5811894de'), 'name': 'string', 'email': 'user2@example.com', 'password': 'string2'}
INFO:     127.0.0.1:38618 - "POST /signin HTTP/1.0" 200 OK
INFO:     127.0.0.1:57038 - "GET /userid HTTP/1.0" 200 OK
INFO:     127.0.0.1:33668 - "GET /SessionId HTTP/1.0" 200 OK
INFO:     127.0.0.1:55396 - "GET /history HTTP/1.0" 200 OK
INFO:     127.0.0.1:41210 - "GET /op/9_md/9/9/9/9/9 HTTP/1.0" 500 Internal Server Error
ERROR:    Exception in ASGI application
Traceback (most recent call last):
  File "/home/ubuntu/.local/lib/python3.10/site-packages/uvicorn/protocols/http/httptools_impl.py", line 426, in run_asgi
    result = await app(  # type: ignore[func-returns-value]
  File "/home/ubuntu/.local/lib/python3.10/site-packages/uvicorn/middleware/proxy_headers.py", line 84, in __call__
    return await self.app(scope, receive, send)
  File "/home/ubuntu/.local/lib/python3.10/site-packages/fastapi/applications.py", line 292, in __call__
    await super().__call__(scope, receive, send)
  File "/home/ubuntu/.local/lib/python3.10/site-packages/starlette/applications.py", line 122, in __call__
    await self.middleware_stack(scope, receive, send)
  File "/home/ubuntu/.local/lib/python3.10/site-packages/starlette/middleware/errors.py", line 184, in __call__
    raise exc
  File "/home/ubuntu/.local/lib/python3.10/site-packages/starlette/middleware/errors.py", line 162, in __call__
    await self.app(scope, receive, _send)
  File "/home/ubuntu/.local/lib/python3.10/site-packages/starlette/middleware/base.py", line 108, in __call__
    response = await self.dispatch_func(request, call_next)
  File "/home/ubuntu/LawGPT_api/main.py", line 123, in auth_middleware
    raise HTTPException(status_code=401, detail="Not authenticated")
fastapi.exceptions.HTTPException
INFO:     127.0.0.1:59206 - "GET /SessionId HTTP/1.0" 200 OK
INFO:     127.0.0.1:49550 - "GET /SessionId HTTP/1.0" 200 OK
INFO:     127.0.0.1:55760 - "GET /.env HTTP/1.0" 500 Internal Server Error
ERROR:    Exception in ASGI application
Traceback (most recent call last):
  File "/home/ubuntu/.local/lib/python3.10/site-packages/uvicorn/protocols/http/httptools_impl.py", line 426, in run_asgi
    result = await app(  # type: ignore[func-returns-value]
  File "/home/ubuntu/.local/lib/python3.10/site-packages/uvicorn/middleware/proxy_headers.py", line 84, in __call__
    return await self.app(scope, receive, send)
  File "/home/ubuntu/.local/lib/python3.10/site-packages/fastapi/applications.py", line 292, in __call__
    await super().__call__(scope, receive, send)
  File "/home/ubuntu/.local/lib/python3.10/site-packages/starlette/applications.py", line 122, in __call__
    await self.middleware_stack(scope, receive, send)
  File "/home/ubuntu/.local/lib/python3.10/site-packages/starlette/middleware/errors.py", line 184, in __call__
    raise exc
  File "/home/ubuntu/.local/lib/python3.10/site-packages/starlette/middleware/errors.py", line 162, in __call__
    await self.app(scope, receive, _send)
  File "/home/ubuntu/.local/lib/python3.10/site-packages/starlette/middleware/base.py", line 108, in __call__
    response = await self.dispatch_func(request, call_next)
  File "/home/ubuntu/LawGPT_api/main.py", line 123, in auth_middleware
    raise HTTPException(status_code=401, detail="Not authenticated")
fastapi.exceptions.HTTPException
INFO:     127.0.0.1:42766 - "HEAD /Core/Skin/Login.aspx HTTP/1.0" 500 Internal Server Error
ERROR:    Exception in ASGI application
Traceback (most recent call last):
  File "/home/ubuntu/.local/lib/python3.10/site-packages/uvicorn/protocols/http/httptools_impl.py", line 426, in run_asgi
    result = await app(  # type: ignore[func-returns-value]
  File "/home/ubuntu/.local/lib/python3.10/site-packages/uvicorn/middleware/proxy_headers.py", line 84, in __call__
    return await self.app(scope, receive, send)
  File "/home/ubuntu/.local/lib/python3.10/site-packages/fastapi/applications.py", line 292, in __call__
    await super().__call__(scope, receive, send)
  File "/home/ubuntu/.local/lib/python3.10/site-packages/starlette/applications.py", line 122, in __call__
    await self.middleware_stack(scope, receive, send)
  File "/home/ubuntu/.local/lib/python3.10/site-packages/starlette/middleware/errors.py", line 184, in __call__
    raise exc
  File "/home/ubuntu/.local/lib/python3.10/site-packages/starlette/middleware/errors.py", line 162, in __call__
    await self.app(scope, receive, _send)
  File "/home/ubuntu/.local/lib/python3.10/site-packages/starlette/middleware/base.py", line 108, in __call__
    response = await self.dispatch_func(request, call_next)
  File "/home/ubuntu/LawGPT_api/main.py", line 123, in auth_middleware
    raise HTTPException(status_code=401, detail="Not authenticated")
fastapi.exceptions.HTTPException
INFO:     127.0.0.1:52130 - "GET /.env HTTP/1.0" 500 Internal Server Error
ERROR:    Exception in ASGI application
Traceback (most recent call last):
  File "/home/ubuntu/.local/lib/python3.10/site-packages/uvicorn/protocols/http/httptools_impl.py", line 426, in run_asgi
    result = await app(  # type: ignore[func-returns-value]
  File "/home/ubuntu/.local/lib/python3.10/site-packages/uvicorn/middleware/proxy_headers.py", line 84, in __call__
    return await self.app(scope, receive, send)
  File "/home/ubuntu/.local/lib/python3.10/site-packages/fastapi/applications.py", line 292, in __call__
    await super().__call__(scope, receive, send)
  File "/home/ubuntu/.local/lib/python3.10/site-packages/starlette/applications.py", line 122, in __call__
    await self.middleware_stack(scope, receive, send)
  File "/home/ubuntu/.local/lib/python3.10/site-packages/starlette/middleware/errors.py", line 184, in __call__
    raise exc
  File "/home/ubuntu/.local/lib/python3.10/site-packages/starlette/middleware/errors.py", line 162, in __call__
    await self.app(scope, receive, _send)
  File "/home/ubuntu/.local/lib/python3.10/site-packages/starlette/middleware/base.py", line 108, in __call__
    response = await self.dispatch_func(request, call_next)
  File "/home/ubuntu/LawGPT_api/main.py", line 123, in auth_middleware
    raise HTTPException(status_code=401, detail="Not authenticated")
fastapi.exceptions.HTTPException
INFO:     127.0.0.1:39252 - "GET /.env HTTP/1.0" 500 Internal Server Error
ERROR:    Exception in ASGI application
Traceback (most recent call last):
  File "/home/ubuntu/.local/lib/python3.10/site-packages/uvicorn/protocols/http/httptools_impl.py", line 426, in run_asgi
    result = await app(  # type: ignore[func-returns-value]
  File "/home/ubuntu/.local/lib/python3.10/site-packages/uvicorn/middleware/proxy_headers.py", line 84, in __call__
    return await self.app(scope, receive, send)
  File "/home/ubuntu/.local/lib/python3.10/site-packages/fastapi/applications.py", line 292, in __call__
    await super().__call__(scope, receive, send)
  File "/home/ubuntu/.local/lib/python3.10/site-packages/starlette/applications.py", line 122, in __call__
    await self.middleware_stack(scope, receive, send)
  File "/home/ubuntu/.local/lib/python3.10/site-packages/starlette/middleware/errors.py", line 184, in __call__
    raise exc
  File "/home/ubuntu/.local/lib/python3.10/site-packages/starlette/middleware/errors.py", line 162, in __call__
    await self.app(scope, receive, _send)
  File "/home/ubuntu/.local/lib/python3.10/site-packages/starlette/middleware/base.py", line 108, in __call__
    response = await self.dispatch_func(request, call_next)
  File "/home/ubuntu/LawGPT_api/main.py", line 123, in auth_middleware
    raise HTTPException(status_code=401, detail="Not authenticated")
fastapi.exceptions.HTTPException
INFO:     127.0.0.1:39268 - "POST / HTTP/1.0" 500 Internal Server Error
ERROR:    Exception in ASGI application
Traceback (most recent call last):
  File "/home/ubuntu/.local/lib/python3.10/site-packages/uvicorn/protocols/http/httptools_impl.py", line 426, in run_asgi
    result = await app(  # type: ignore[func-returns-value]
  File "/home/ubuntu/.local/lib/python3.10/site-packages/uvicorn/middleware/proxy_headers.py", line 84, in __call__
    return await self.app(scope, receive, send)
  File "/home/ubuntu/.local/lib/python3.10/site-packages/fastapi/applications.py", line 292, in __call__
    await super().__call__(scope, receive, send)
  File "/home/ubuntu/.local/lib/python3.10/site-packages/starlette/applications.py", line 122, in __call__
    await self.middleware_stack(scope, receive, send)
  File "/home/ubuntu/.local/lib/python3.10/site-packages/starlette/middleware/errors.py", line 184, in __call__
    raise exc
  File "/home/ubuntu/.local/lib/python3.10/site-packages/starlette/middleware/errors.py", line 162, in __call__
    await self.app(scope, receive, _send)
  File "/home/ubuntu/.local/lib/python3.10/site-packages/starlette/middleware/base.py", line 108, in __call__
    response = await self.dispatch_func(request, call_next)
  File "/home/ubuntu/LawGPT_api/main.py", line 123, in auth_middleware
    raise HTTPException(status_code=401, detail="Not authenticated")
fastapi.exceptions.HTTPException
INFO:     127.0.0.1:41328 - "GET /Temporary_Listen_Addresses HTTP/1.0" 500 Internal Server Error
ERROR:    Exception in ASGI application
Traceback (most recent call last):
  File "/home/ubuntu/.local/lib/python3.10/site-packages/uvicorn/protocols/http/httptools_impl.py", line 426, in run_asgi
    result = await app(  # type: ignore[func-returns-value]
  File "/home/ubuntu/.local/lib/python3.10/site-packages/uvicorn/middleware/proxy_headers.py", line 84, in __call__
    return await self.app(scope, receive, send)
  File "/home/ubuntu/.local/lib/python3.10/site-packages/fastapi/applications.py", line 292, in __call__
    await super().__call__(scope, receive, send)
  File "/home/ubuntu/.local/lib/python3.10/site-packages/starlette/applications.py", line 122, in __call__
    await self.middleware_stack(scope, receive, send)
  File "/home/ubuntu/.local/lib/python3.10/site-packages/starlette/middleware/errors.py", line 184, in __call__
    raise exc
  File "/home/ubuntu/.local/lib/python3.10/site-packages/starlette/middleware/errors.py", line 162, in __call__
    await self.app(scope, receive, _send)
  File "/home/ubuntu/.local/lib/python3.10/site-packages/starlette/middleware/base.py", line 108, in __call__
    response = await self.dispatch_func(request, call_next)
  File "/home/ubuntu/LawGPT_api/main.py", line 123, in auth_middleware
    raise HTTPException(status_code=401, detail="Not authenticated")
fastapi.exceptions.HTTPException
INFO:     127.0.0.1:41334 - "GET /Pages/log/ HTTP/1.0" 500 Internal Server Error
ERROR:    Exception in ASGI application
Traceback (most recent call last):
  File "/home/ubuntu/.local/lib/python3.10/site-packages/uvicorn/protocols/http/httptools_impl.py", line 426, in run_asgi
    result = await app(  # type: ignore[func-returns-value]
  File "/home/ubuntu/.local/lib/python3.10/site-packages/uvicorn/middleware/proxy_headers.py", line 84, in __call__
    return await self.app(scope, receive, send)
  File "/home/ubuntu/.local/lib/python3.10/site-packages/fastapi/applications.py", line 292, in __call__
    await super().__call__(scope, receive, send)
  File "/home/ubuntu/.local/lib/python3.10/site-packages/starlette/applications.py", line 122, in __call__
    await self.middleware_stack(scope, receive, send)
  File "/home/ubuntu/.local/lib/python3.10/site-packages/starlette/middleware/errors.py", line 184, in __call__
    raise exc
  File "/home/ubuntu/.local/lib/python3.10/site-packages/starlette/middleware/errors.py", line 162, in __call__
    await self.app(scope, receive, _send)
  File "/home/ubuntu/.local/lib/python3.10/site-packages/starlette/middleware/base.py", line 108, in __call__
    response = await self.dispatch_func(request, call_next)
  File "/home/ubuntu/LawGPT_api/main.py", line 123, in auth_middleware
    raise HTTPException(status_code=401, detail="Not authenticated")
fastapi.exceptions.HTTPException
INFO:     127.0.0.1:55510 - "GET /.env HTTP/1.0" 500 Internal Server Error
ERROR:    Exception in ASGI application
Traceback (most recent call last):
  File "/home/ubuntu/.local/lib/python3.10/site-packages/uvicorn/protocols/http/httptools_impl.py", line 426, in run_asgi
    result = await app(  # type: ignore[func-returns-value]
  File "/home/ubuntu/.local/lib/python3.10/site-packages/uvicorn/middleware/proxy_headers.py", line 84, in __call__
    return await self.app(scope, receive, send)
  File "/home/ubuntu/.local/lib/python3.10/site-packages/fastapi/applications.py", line 292, in __call__
    await super().__call__(scope, receive, send)
  File "/home/ubuntu/.local/lib/python3.10/site-packages/starlette/applications.py", line 122, in __call__
    await self.middleware_stack(scope, receive, send)
  File "/home/ubuntu/.local/lib/python3.10/site-packages/starlette/middleware/errors.py", line 184, in __call__
    raise exc
  File "/home/ubuntu/.local/lib/python3.10/site-packages/starlette/middleware/errors.py", line 162, in __call__
    await self.app(scope, receive, _send)
  File "/home/ubuntu/.local/lib/python3.10/site-packages/starlette/middleware/base.py", line 108, in __call__
    response = await self.dispatch_func(request, call_next)
  File "/home/ubuntu/LawGPT_api/main.py", line 123, in auth_middleware
    raise HTTPException(status_code=401, detail="Not authenticated")
fastapi.exceptions.HTTPException
INFO:     127.0.0.1:55526 - "POST / HTTP/1.0" 500 Internal Server Error
ERROR:    Exception in ASGI application
Traceback (most recent call last):
  File "/home/ubuntu/.local/lib/python3.10/site-packages/uvicorn/protocols/http/httptools_impl.py", line 426, in run_asgi
    result = await app(  # type: ignore[func-returns-value]
  File "/home/ubuntu/.local/lib/python3.10/site-packages/uvicorn/middleware/proxy_headers.py", line 84, in __call__
    return await self.app(scope, receive, send)
  File "/home/ubuntu/.local/lib/python3.10/site-packages/fastapi/applications.py", line 292, in __call__
    await super().__call__(scope, receive, send)
  File "/home/ubuntu/.local/lib/python3.10/site-packages/starlette/applications.py", line 122, in __call__
    await self.middleware_stack(scope, receive, send)
  File "/home/ubuntu/.local/lib/python3.10/site-packages/starlette/middleware/errors.py", line 184, in __call__
    raise exc
  File "/home/ubuntu/.local/lib/python3.10/site-packages/starlette/middleware/errors.py", line 162, in __call__
    await self.app(scope, receive, _send)
  File "/home/ubuntu/.local/lib/python3.10/site-packages/starlette/middleware/base.py", line 108, in __call__
    response = await self.dispatch_func(request, call_next)
  File "/home/ubuntu/LawGPT_api/main.py", line 123, in auth_middleware
    raise HTTPException(status_code=401, detail="Not authenticated")
fastapi.exceptions.HTTPException
